<?xml version="0.0" ?>
<robot name="pupper_v2_dji">
	<link name="pupper_v2_dji_chassis">
		<inertial>
			<origin rpy="0.00000 -0.00000 0.00000" xyz="0.00000 0.00000 0.00000"/>
			<mass value="1.00000"/>
			<inertia ixx="0.00649" ixy="0" ixz="0" iyy="0.00205" iyz="0" izz="0.00717"/>
		</inertial>
		<visual>
			<origin rpy="0.00000 -0.00000 0.00000" xyz="0.00000 0.00000 0.00000"/>
			<geometry>
				<mesh filename="meshes/chassis_top.obj" scale="1.00000 1.00000 1.00000"/>
			</geometry>
			<material name="mat_-1_0">
				<color rgba="1.00000 1.00000 1.00000 1.00000" />
			</material>
		</visual>
		<visual>
			<origin rpy="0.00000 -0.00000 0.00000" xyz="0.00000 0.00000 0.00000"/>
			<geometry>
				<mesh filename="meshes/chassis_bottom.obj" scale="1.00000 1.00000 1.00000"/>
			</geometry>
			<material name="mat_-1_1">
				<color rgba="1.00000 1.00000 1.00000 1.00000" />
			</material>
		</visual>
		<visual>
			<origin rpy="0.00000 -0.00000 0.00000" xyz="0.00000 0.00000 0.00000"/>
			<geometry>
				<mesh filename="meshes/chassis_right.obj" scale="1.00000 1.00000 1.00000"/>
			</geometry>
			<material name="mat_-1_2">
				<color rgba="1.00000 1.00000 1.00000 1.00000" />
			</material>
		</visual>
		<visual>
			<origin rpy="0.00000 -0.00000 0.00000" xyz="0.00000 0.00000 0.00000"/>
			<geometry>
				<mesh filename="meshes/chassis_left.obj" scale="1.00000 1.00000 1.00000"/>
			</geometry>
			<material name="mat_-1_3">
				<color rgba="1.00000 1.00000 1.00000 1.00000" />
			</material>
		</visual>
		<visual>
			<origin rpy="0.00000 -0.00000 0.00000" xyz="0.00000 0.00000 0.00000"/>
			<geometry>
				<mesh filename="meshes/chassis_back.obj" scale="1.00000 1.00000 1.00000"/>
			</geometry>
			<material name="mat_-1_4">
				<color rgba="1.00000 1.00000 1.00000 1.00000" />
			</material>
		</visual>
		<visual>
			<origin rpy="0.00000 -0.00000 0.00000" xyz="0.00000 0.00000 0.00000"/>
			<geometry>
				<mesh filename="meshes/chassis_front.obj" scale="1.00000 1.00000 1.00000"/>
			</geometry>
			<material name="mat_-1_5">
				<color rgba="1.00000 1.00000 1.00000 1.00000" />
			</material>
		</visual>
		<collision>
			<origin rpy="0.00000 -0.00000 0.00000" xyz="0.00000 0.00000 0.00000"/>
			<geometry>
				<box size="0.124754 0.261898 0.089444"/>
			</geometry>
		</collision>
	
	</link>
	<link name="leftRearLeg">
		<inertial>
			<origin rpy="0.00000 -0.00000 0.00000" xyz="0.00000 0.015  0.00000"/>
			<mass value="0.20000"/>
			<inertia ixx="0.00017" ixy="0" ixz="0" iyy="0.00022" iyz="0" izz="0.00022"/>
		</inertial>
		<visual>
			<origin rpy="0.00000 -0.00000 0.00000" xyz="-0.04645 -0.13313 -0.00483"/>
			<geometry>
				<mesh filename="meshes/bracket_left_rear.obj" scale="1.00000 1.00000 1.00000"/>
			</geometry>
			<material name="mat_0_0">
				<color rgba="1.00000 1.00000 1.00000 1.00000" />
			</material>
		</visual>
		<visual>
			<origin rpy="0.00000 -0.00000 0.00000" xyz="-0.04645 -0.13313 -0.00483"/>
			<geometry>
				<mesh filename="meshes/motor_left_rear.obj" scale="1.00000 1.00000 1.00000"/>
			</geometry>
			<material name="mat_0_1">
				<color rgba="1.00000 1.00000 1.00000 1.00000" />
			</material>
		</visual>
		
		<collision>
			<origin rpy="0.00000 1.57000 0.000000" xyz="0.01 0.02000 0.0000"/>
			<geometry>
				<capsule length="0.04" radius="0.01"/>
			</geometry>
		</collision>
	</link>
	<link name="leftRearUpperLeg">
		<inertial>
			<origin rpy="0.00000 -0.00000 0.00000" xyz="0.02000 0.00000 -0.05000"/>
			<mass value="0.20000"/>
			<inertia ixx="0.00024" ixy="0" ixz="0" iyy="0.00031" iyz="0" izz="0.00011"/>
		</inertial>
		<visual>
			<origin rpy="0.00000 -0.00000 0.00000" xyz="0.00000 0.00000 0.00000"/>
			<geometry>
				<mesh filename="meshes/upper_leg_left_rear.obj" scale="1.00000 1.00000 1.00000"/>
			</geometry>
			<material name="mat_1_0">
				<color rgba="1.00000 1.00000 1.00000 1.00000" />
			</material>
		</visual>
		<collision>
			<origin rpy="0.00000 -0.00000 0.00000" xyz="0.01000 0.00000 -0.03000"/>
			<geometry>
				<capsule length="0.08" radius="0.005"/>
			</geometry>
		</collision>
		<collision>
			<origin rpy="0.00000 1.57000 0.000000" xyz="0.0350 0.00000 -0.08000"/>
			<geometry>
				<capsule length="0.04" radius="0.01"/>
			</geometry>
		</collision>
		
	</link>
	<link name="leftRearLowerLeg">
		<inertial>
			<origin rpy="0.00000 -0.00000 0.00000" xyz="0.01000 0.00000 -0.05000"/>
			<mass value="0.10000"/>
			<inertia ixx="0.00017" ixy="0" ixz="0" iyy="0.00017" iyz="0" izz="0.00001"/>
		</inertial>
		<visual>
			<origin rpy="0.00000 -0.00000 0.00000" xyz="0.00000 0.00000 0.00000"/>
			<geometry>
				<mesh filename="meshes/lower_leg_left_rear.obj" scale="1.00000 1.00000 1.00000"/>
			</geometry>
			<material name="mat_2_0">
				<color rgba="1.00000 1.00000 1.00000 1.00000" />
			</material>
		</visual>
		<collision>
			<origin rpy="0.00000 -0.00000 0.00000" xyz="0.005 0.00000 -0.05"/>
			<geometry>
				<capsule length="0.11" radius="0.005"/>
			</geometry>
		</collision>
	
	</link>
	<link name="leftRearToe">
		<inertial>
			<origin rpy="0.00000 -0.00000 0.00000" xyz="0.0000 0.00000 0.0000"/>
			<mass value="0.010000"/>
			<inertia ixx="0.000017" ixy="0" ixz="0" iyy="0.000017" iyz="0" izz="0.000001"/>
		</inertial>
		
		<visual>
			<origin rpy="0.00000 -0.00000 0.00000" xyz="0.00 0.00000 0.000"/>
			<geometry>
				<sphere radius="0.01"/>
			</geometry>
			<material name="blue">
				<color rgba=".100000 .100000 1.00000 1.00000" />
			</material>
		</visual>
		
		<collision>
			<origin rpy="0.00000 -0.00000 0.00000" xyz="0.00 0.00000 0.000"/>
			<geometry>
				<sphere radius="0.01"/>
			</geometry>
		</collision>
	</link>
	<link name="rightRearLeg">
		<inertial>
			<origin rpy="0.00000 -0.00000 0.00000" xyz="0.00000 0.015  0.00000"/>
			<mass value="0.20000"/>
			<inertia ixx="0.00017" ixy="0" ixz="0" iyy="0.00022" iyz="0" izz="0.00022"/>
		</inertial>
		<visual>
			<origin rpy="0.00000 -0.00000 0.00000" xyz="0.04646 -0.13313 -0.00483"/>
			<geometry>
				<mesh filename="meshes/bracket_right_rear.obj" scale="1.00000 1.00000 1.00000"/>
			</geometry>
			<material name="mat_3_0">
				<color rgba="1.00000 1.00000 1.00000 1.00000" />
			</material>
		</visual>
		<visual>
			<origin rpy="0.00000 -0.00000 0.00000" xyz="0.04646 -0.13313 -0.00483"/>
			<geometry>
				<mesh filename="meshes/motor_right_rear.obj" scale="1.00000 1.00000 1.00000"/>
			</geometry>
			<material name="mat_3_1">
				<color rgba="1.00000 1.00000 1.00000 1.00000" />
			</material>
		</visual>
	<collision>
			<origin rpy="0.00000 1.57000 0.000000" xyz="-0.01 0.02000 0.0000"/>
			<geometry>
				<capsule length="0.04" radius="0.01"/>
			</geometry>
		</collision>
		
	</link>
	<link name="rightRearUpperLeg">
		<inertial>
			<origin rpy="0.00000 -0.00000 0.00000" xyz="-0.02000 0.00000 -0.05000"/>
			<mass value="0.20000"/>
			<inertia ixx="0.00024" ixy="0" ixz="0" iyy="0.00031" iyz="0" izz="0.00011"/>
		</inertial>
		<visual>
			<origin rpy="0.00000 -0.00000 0.00000" xyz="0.00000 0.00000 0.00000"/>
			<geometry>
				<mesh filename="meshes/upper_leg_right_rear.obj" scale="1.00000 1.00000 1.00000"/>
			</geometry>
			<material name="mat_4_0">
				<color rgba="1.00000 1.00000 1.00000 1.00000" />
			</material>
		</visual>
		<collision>
			<origin rpy="0.00000 -0.00000 0.00000" xyz="-0.01000 0.00000 -0.03000"/>
			<geometry>
				<capsule length="0.08" radius="0.005"/>
			</geometry>
		</collision>
		<collision>
			<origin rpy="0.00000 -1.57000 0.000000" xyz="-0.0350 0.00000 -0.08000"/>
			<geometry>
				<capsule length="0.04" radius="0.01"/>
			</geometry>
		</collision>
	</link>
	<link name="rightRearLowerLeg">
		<inertial>
			<origin rpy="0.00000 -0.00000 0.00000" xyz="-0.01000 0.00000 -0.05000"/>
			<mass value="0.10000"/>
			<inertia ixx="0.00017" ixy="0" ixz="0" iyy="0.00017" iyz="0" izz="0.00001"/>
		</inertial>
		<visual>
			<origin rpy="0.00000 -0.00000 0.00000" xyz="0.00000 0.00000 0.00000"/>
			<geometry>
				<mesh filename="meshes/lower_leg_right_rear.obj" scale="1.00000 1.00000 1.00000"/>
			</geometry>
			<material name="mat_5_0">
				<color rgba="1.00000 1.00000 1.00000 1.00000" />
			</material>
		</visual>
			<collision>
			<origin rpy="0.00000 -0.00000 0.00000" xyz="-0.005 0.00000 -0.05"/>
			<geometry>
				<capsule length="0.11" radius="0.005"/>
			</geometry>
		</collision>
	</link>
	<link name="rightRearToe">
		<inertial>
			<origin rpy="0.00000 -0.00000 0.00000" xyz="0.0000 0.00000 -0.0000"/>
			<mass value="0.01"/>
			<inertia ixx="0.000017" ixy="0" ixz="0" iyy="0.000017" iyz="0" izz="0.000001"/>
		</inertial>
					
		<visual>
			<origin rpy="0.00000 -0.00000 0.00000" xyz="0.0 0.0 0.00"/>
			<geometry>
				<sphere radius="0.01"/>
			</geometry>
			<material name="black">
				<color rgba=".100000 .100000 .100000 1.00000" />
			</material>
		</visual>
		
		<collision>
			<origin rpy="0.00000 -0.00000 0.00000" xyz="0.00 0.00000 0.000"/>
			<geometry>
				<sphere radius="0.01"/>
			</geometry>
		</collision>
	</link>
	<link name="leftFrontLeg">
		<inertial>
			<origin rpy="0.00000 -0.00000 0.00000" xyz="0.00000 0.015  0.00000"/>
			<mass value="0.20000"/>
			<inertia ixx="0.00018" ixy="0" ixz="0" iyy="0.00023" iyz="0" izz="0.00022"/>
		</inertial>
		<visual>
			<origin rpy="0.00000 -0.00000 0.00000" xyz="-0.04645 0.06686 -0.00483"/>
			<geometry>
				<mesh filename="meshes/bracket_left.obj" scale="1.00000 1.00000 1.00000"/>
			</geometry>
			<material name="mat_6_0">
				<color rgba="1.00000 1.00000 1.00000 1.00000" />
			</material>
		</visual>
		<visual>
			<origin rpy="0.00000 -0.00000 0.00000" xyz="-0.04645 0.06686 -0.00483"/>
			<geometry>
				<mesh filename="meshes/motor_left_front.obj" scale="1.00000 1.00000 1.00000"/>
			</geometry>
			<material name="mat_6_1">
				<color rgba="1.00000 1.00000 1.00000 1.00000" />
			</material>
		</visual>
		<collision>
			<origin rpy="0.00000 1.57000 0.000000" xyz="0.01 0.02000 0.0000"/>
			<geometry>
				<capsule length="0.04" radius="0.01"/>
			</geometry>
		</collision>
		
	</link>
	<link name="leftFrontUpperLeg">
		<inertial>
			<origin rpy="0.00000 -0.00000 0.00000" xyz="0.02000 0.00000 -0.05000"/>
			<mass value="0.20000"/>
			<inertia ixx="0.00024" ixy="0" ixz="0" iyy="0.00031" iyz="0" izz="0.00011"/>
		</inertial>
		<visual>
			<origin rpy="0.00000 -0.00000 0.00000" xyz="0.00000 0.00000 0.00000"/>
			<geometry>
				<mesh filename="meshes/upper_leg_left_rear.obj" scale="1.00000 1.00000 1.00000"/>
			</geometry>
			<material name="mat_7_0">
				<color rgba="1.00000 1.00000 1.00000 1.00000" />
			</material>
		</visual>
		<collision>
			<origin rpy="0.00000 -0.00000 0.00000" xyz="0.01000 0.00000 -0.03000"/>
			<geometry>
				<capsule length="0.08" radius="0.005"/>
			</geometry>
		</collision>
		<collision>
			<origin rpy="0.00000 -1.57000 0.000000" xyz="0.0350 0.00000 -0.08000"/>
			<geometry>
				<capsule length="0.04" radius="0.01"/>
			</geometry>
		</collision>
	</link>
	<link name="leftFrontLowerLeg">
		<inertial>
			<origin rpy="0.00000 -0.00000 0.00000" xyz="0.01000 0.00000 -0.05000"/>
			<mass value="0.10000"/>
			<inertia ixx="0.00017" ixy="0" ixz="0" iyy="0.00017" iyz="0" izz="0.00001"/>
		</inertial>
		<visual>
			<origin rpy="0.00000 -0.00000 0.00000" xyz="0.00000 0.00000 0.00000"/>
			<geometry>
				<mesh filename="meshes/lower_leg_left_rear.obj" scale="1.00000 1.00000 1.00000"/>
			</geometry>
			<material name="mat_8_0">
				<color rgba="1.00000 1.00000 1.00000 1.00000" />
			</material>
		</visual>
			<collision>
			<origin rpy="0.00000 -0.00000 0.00000" xyz="0.005 0.00000 -0.05"/>
			<geometry>
				<capsule length="0.11" radius="0.005"/>
			</geometry>
		</collision>
	</link>
		<link name="leftFrontToe">
		<inertial>
			<origin rpy="0.00000 -0.00000 0.00000" xyz="0.0000 0.00000 0.0000"/>
			<mass value="0.010000"/>
			<inertia ixx="0.000017" ixy="0" ixz="0" iyy="0.000017" iyz="0" izz="0.000001"/>
		</inertial>
		
		<visual>
			<origin rpy="0.00000 -0.00000 0.00000" xyz="0.00 0.00000 0.000"/>
			<geometry>
				<sphere radius="0.01"/>
			</geometry>
			<material name="red">
				<color rgba="1.00000 .100000 .100000 1.00000" />
			</material>
		</visual>
		
		<collision>
			<origin rpy="0.00000 -0.00000 0.00000" xyz="0.00 0.00000 0.000"/>
			<geometry>
				<sphere radius="0.01"/>
			</geometry>
		</collision>
	</link>
	<link name="rightFrontLeg">
		<inertial>
			<origin rpy="0.00000 -0.00000 0.00000" xyz="0.00000 0.015  0.00000"/>
			<mass value="0.20000"/>
			<inertia ixx="0.00018" ixy="0" ixz="0" iyy="0.00023" iyz="0" izz="0.00022"/>
		</inertial>
		<visual>
			<origin rpy="0.00000 -0.00000 0.00000" xyz="0.04645 0.06686 -0.00483"/>
			<geometry>
				<mesh filename="meshes/motor_right_front.obj" scale="1.00000 1.00000 1.00000"/>
			</geometry>
			<material name="mat_9_0">
				<color rgba="1.00000 1.00000 1.00000 1.00000" />
			</material>
		</visual>
		<collision>
			<origin rpy="0.00000 -1.57000 0.000000" xyz="-0.01 0.02000 0.0000"/>
			<geometry>
				<capsule length="0.04" radius="0.01"/>
			</geometry>
		</collision>
		
	</link>
	<link name="rightFrontUpperLeg">
		<inertial>
			<origin rpy="0.00000 -0.00000 0.00000" xyz="-0.02000 0.00000 -0.05000"/>
			<mass value="0.20000"/>
			<inertia ixx="0.00024" ixy="0" ixz="0" iyy="0.00031" iyz="0" izz="0.00011"/>
		</inertial>
		<visual>
			<origin rpy="0.00000 -0.00000 0.00000" xyz="0.00000 0.00000 0.00000"/>
			<geometry>
				<mesh filename="meshes/upper_leg_right_rear.obj" scale="1.00000 1.00000 1.00000"/>
			</geometry>
			<material name="mat_10_0">
				<color rgba="1.00000 1.00000 1.00000 1.00000" />
			</material>
		</visual>
	<collision>
			<origin rpy="0.00000 -0.00000 0.00000" xyz="-0.01000 0.00000 -0.03000"/>
			<geometry>
				<capsule length="0.08" radius="0.005"/>
			</geometry>
		</collision>
		<collision>
			<origin rpy="0.00000 -1.57000 0.000000" xyz="-0.0350 0.00000 -0.08000"/>
			<geometry>
				<capsule length="0.04" radius="0.01"/>
			</geometry>
		</collision>
	</link>
	<link name="rightFrontLowerLeg">
		<inertial>
			<origin rpy="0.00000 -0.00000 0.00000" xyz="-0.01000 0.00000 -0.05000"/>
			<mass value="0.10000"/>
			<inertia ixx="0.00017" ixy="0" ixz="0" iyy="0.00017" iyz="0" izz="0.00001"/>
		</inertial>
		<visual>
			<origin rpy="0.00000 -0.00000 0.00000" xyz="0.00000 0.00000 0.00000"/>
			<geometry>
				<mesh filename="meshes/lower_leg_right_rear.obj" scale="1.00000 1.00000 1.00000"/>
			</geometry>
			<material name="mat_11_0">
				<color rgba="1.00000 1.00000 1.00000 1.00000" />
			</material>
		</visual>
		<collision>
			<origin rpy="0.00000 -0.00000 0.00000" xyz="-0.005 0.00000 -0.05"/>
			<geometry>
				<capsule length="0.11" radius="0.005"/>
			</geometry>
		</collision>

	</link>
	
	
	
	<link name="rightFrontToe">
		<inertial>
			<origin rpy="0.00000 -0.00000 0.00000" xyz="0.0000 0.00000 0.0000"/>
			<mass value="0.010000"/>
			<inertia ixx="0.000017" ixy="0" ixz="0" iyy="0.000017" iyz="0" izz="0.000001"/>
		</inertial>
		
		<visual>
			<origin rpy="0.00000 -0.00000 0.00000" xyz="0.00 0.00000 0.000"/>
			<geometry>
				<sphere radius="0.01"/>
			</geometry>
				<material name="green">
				<color rgba=".100000 1.00000 .100000 1.00000" />
			</material>
		</visual>
		
		<collision>
			<origin rpy="0.00000 -0.00000 0.00000" xyz="0.00 0.00000 0.000"/>
			<geometry>
				<sphere radius="0.01"/>
			</geometry>
		</collision>
	</link>
	
  <joint name="rightFrontLegMotor" type="revolute">
		<parent link="pupper_v2_dji_chassis"/>
		<child link="rightFrontLeg"/>
		<dynamics damping="0.0" friction="0.0001"/>
		<origin rpy="0.00000 -0.00000 0.00000" xyz="-0.04645 -0.06686 0.00483"/>
		<axis xyz="0.00000 -1.00000 0.00000"/>
		<limit effort="100" velocity="100" lower="-0.2" upper=".2"/>
	</joint>
	<joint name="rightFrontUpperLegMotor" type="revolute">
		<parent link="rightFrontLeg"/>
		<child link="rightFrontUpperLeg"/>
		<dynamics damping="0.0" friction="0.0001"/>
		<origin rpy="0.00000 -0.00000 0.00000" xyz="-0.02500 0.02000 -0.00500"/>
		<axis xyz="1.00000 0.00000 0.00000"/>
		<limit effort="100" velocity="100" lower="0.0" upper=".8"/>
	</joint>
	<joint name="rightFrontLowerLegMotor" type="revolute">
		<parent link="rightFrontUpperLeg"/>
		<child link="rightFrontLowerLeg"/>
		<dynamics damping="0.0" friction="0.0001"/>
		<origin rpy="0.00000 -0.00000 0.00000" xyz="0.00000 0.00000 -0.08000"/>
		<axis xyz="1.00000 0.00000 0.00000"/>
		<limit effort="100" velocity="100" lower="-2.4" upper="-.5"/>
	</joint>
	
	<joint name="leftFrontLegMotor" type="revolute">
		<parent link="pupper_v2_dji_chassis"/>
		<child link="leftFrontLeg"/>
		<dynamics damping="0.0" friction="0.0001"/>
		<origin rpy="0.00000 -0.00000 0.00000" xyz="0.04645 -0.06686 0.00483"/>
		<axis xyz="0.00000 -1.00000 0.00000"/>
		<limit effort="100" velocity="100" lower="-0.2" upper=".2"/>
	</joint>
	<joint name="leftFrontUpperLegMotor" type="revolute">
		<parent link="leftFrontLeg"/>
		<child link="leftFrontUpperLeg"/>
		<dynamics damping="0.0" friction="0.0001"/>
		<origin rpy="0.00000 -0.00000 0.00000" xyz="0.02500 0.02000 -0.00500"/>
		<axis xyz="1.00000 0.00000 0.00000"/>
		<limit effort="100" velocity="100" lower="0.0" upper=".8"/>
	</joint>
	<joint name="leftFrontLowerLegMotor" type="revolute">
		<parent link="leftFrontUpperLeg"/>
		<child link="leftFrontLowerLeg"/>
		<dynamics damping="0.0" friction="0.0001"/>
		<origin rpy="0.00000 -0.00000 0.00000" xyz="0.00000 0.00000 -0.08000"/>
		<axis xyz="1.00000 0.00000 0.00000"/>
		<limit effort="100" velocity="100" lower="-2.4" upper="-.5"/>
	</joint>
	
	
	<joint name="rightRearLegMotor" type="revolute">
		<parent link="pupper_v2_dji_chassis"/>
		<child link="rightRearLeg"/>
		<dynamics damping="0.0" friction="0.0001"/>
		<origin rpy="0.00000 -0.00000 0.00000" xyz="-0.04645 0.13313 0.00483"/>
		<axis xyz="0.00000 -1.00000 0.00000"/>
		<limit effort="100" velocity="100" lower="-0.2" upper=".2"/>
	</joint>
	<joint name="rightRearUpperLegMotor" type="revolute">
		<parent link="rightRearLeg"/>
		<child link="rightRearUpperLeg"/>
		<dynamics damping="0.0" friction="0.0001"/>
		<origin rpy="0.00000 -0.00000 0.00000" xyz="-0.02500 0.02000 -0.00500"/>
		<axis xyz="1.00000 0.00000 0.00000"/>
		<limit effort="100" velocity="100" lower="0.0" upper=".8"/>
	</joint>
	<joint name="rightRearLowerLegMotor" type="revolute">
		<parent link="rightRearUpperLeg"/>
		<child link="rightRearLowerLeg"/>
		<dynamics damping="0.0" friction="0.0001"/>
		<origin rpy="0.00000 -0.00000 0.00000" xyz="0.00000 0.00000 -0.08000"/>
		<axis xyz="1.00000 0.00000 0.00000"/>
		<limit effort="100" velocity="100" lower="-2.4" upper="-.5"/>
	</joint>
	<joint name="leftRearLegMotor" type="revolute">
		<parent link="pupper_v2_dji_chassis"/>
		<child link="leftRearLeg"/>
		<dynamics damping="0.0" friction="0.0001"/>
		<origin rpy="0.00000 -0.00000 0.00000" xyz="0.04645 0.13313 0.00483"/>
		<axis xyz="0.00000 -1.00000 0.00000"/>
		<limit effort="100" velocity="100" lower="-0.2" upper=".2"/>
	</joint>
	<joint name="leftRearUpperLegMotor" type="revolute">
		<parent link="leftRearLeg"/>
		<child link="leftRearUpperLeg"/>
		<dynamics damping="0.0" friction="0.0001"/>
		<origin rpy="0.00000 -0.00000 0.00000" xyz="0.02500 0.02000 -0.00500"/>
		<axis xyz="1.00000 0.00000 0.00000"/>
		<limit effort="100" velocity="100" lower="0.0" upper=".8"/>
	</joint>
	<joint name="leftRearLowerLegMotor" type="revolute">
		<parent link="leftRearUpperLeg"/>
		<child link="leftRearLowerLeg"/>
		<dynamics damping="0.0" friction="0.0001"/>
		<origin rpy="0.00000 -0.00000 0.00000" xyz="0.00000 0.00000 -0.08000"/>
		<axis xyz="1.00000 0.00000 0.00000"/>
		<limit effort="100" velocity="100" lower="-2.4" upper="-.5"/>
	</joint>
	<joint name="leftRearToe" type="fixed">
		<parent link="leftRearLowerLeg"/>
		<child link="leftRearToe"/>
		<dynamics damping="0.0" friction="0.0001"/>
		<origin rpy="0.00000 -0.00000 0.00000" xyz="0.0094 0.00000 -0.11000"/>
		<axis xyz="1.00000 0.00000 0.00000"/>
	</joint>
	
	<joint name="rightFrontToe" type="fixed">
		<parent link="rightFrontLowerLeg"/>
		<child link="rightFrontToe"/>
		<dynamics damping="0.0" friction="0.0001"/>
		<origin rpy="0.00000 -0.00000 0.00000" xyz="-0.0094 0.00000 -0.11000"/>
		<axis xyz="1.00000 0.00000 0.00000"/>
	</joint>
	<joint name="leftFrontToe" type="fixed">
		<parent link="leftFrontLowerLeg"/>
		<child link="leftFrontToe"/>
		<dynamics damping="0.0" friction="0.0001"/>
		<origin rpy="0.00000 -0.00000 0.00000" xyz="0.0094 0.00000 -0.11000"/>
		<axis xyz="1.00000 0.00000 0.00000"/>
	</joint>
	<joint name="rightRearToe" type="fixed">
		<parent link="rightRearLowerLeg"/>
		<child link="rightRearToe"/>
		<dynamics damping="0.0" friction="0.0001"/>
		<origin rpy="0.00000 -0.00000 0.00000" xyz="-0.0094 0.00000 -0.11000"/>
		<axis xyz="1.00000 0.00000 0.00000"/>
	</joint>	
</robot>
